<?xml version="1.0" ?>
<!-- =================================================================================== -->
<!-- |    This document was autogenerated by xacro from rbcar.urdf.xacro               | -->
<!-- |    EDITING THIS FILE BY HAND IS NOT RECOMMENDED                                 | -->
<!-- =================================================================================== -->
<robot name="rbcar" xmlns:xacro="http://ros.org/wiki/xacro">
  <!-- ***************** -->
  <!-- Imported elements -->
  <!-- ***************** -->
  <!-- First we import all posible elements defined in the urdf.xacro files. All these elements are defined as macro:xacros -->
  <!-- Import Robotnik CAR base elements -->
  <gazebo reference="base_footprint">
    <material>Gazebo/Green</material>
  </gazebo>
  <!-- Import Robotnik CAR wheels -->
  <!-- Import all available sensors -->
  <!-- ***************** -->
  <!-- Global parameters -->
  <!-- ***************** -->
  <!-- Wheel parameters -->
  <!-- x,y,z in translation from base_link to the center of the wheel -->
  <!-- Flag to select the high or low quality model -->
  <!-- *************** -->
  <!-- Robots Elements -->
  <!-- *************** -->
  <!-- Here we create the robot elements using the xacro:macros imported at the beggining of this file -->
  <!-- Summit XL base -->
  <xacro:property name="PI" value="3.1415926535897931"/>
  <xacro:property name="wheel_width" value="0.175"/>
  <link name="base_footprint">
    <visual>
      <origin rpy="0 0 0" xyz="0 0 0"/>
      <geometry>
        <box size="0.001 0.001 0.001"/>
      </geometry>
    </visual>
    <!--
      <collision>
          <origin xyz="0 0 0" rpy="0 0 0" />
          <geometry>
            <box size="0.001 0.001 0.001" />
          </geometry>
      </collision>
-->
  </link>
  <joint name="base_footprint_joint" type="fixed">
    <!-- origin xyz="0 0 ${wheel_radius}" rpy="0 0 0" / -->
    <!-- ${wheel_radius} property must be defined inside wheel description -->
    <origin rpy="0 0 0" xyz="0 0 0.235"/>
    <!-- ${wheel_radius} property must be defined inside wheel description -->
    <parent link="base_footprint"/>
    <child link="base_link"/>
  </joint>
  <link name="base_link">
    <inertial>
      <mass value="250.0"/>
      <origin xyz="0 0 0"/>
      <inertia ixx="1.391" ixy="0.004" ixz="0.0" iyy="6.853" iyz="0.0" izz="6.125"/>
    </inertial>
    <visual>
      <origin rpy="0 0 0" xyz="0 0 0"/>
      <geometry>
        <mesh filename="package://rbcar_description/meshes/bases/rbcar_chassis.dae"/>
      </geometry>
      <material name="darkgrey">
        <color rgba="0.1 0.1 0.1 1"/>
      </material>
    </visual>
    <collision>
      <origin rpy="0 0 0 " xyz="0 0 0"/>
      <geometry>
        <mesh filename="package://rbcar_description/meshes/bases/rbcar_chassis.dae"/>
      </geometry>
    </collision>
  </link>
  <!-- Gazebo ros control pluggins -->
  <xacro:ros_control/>
  <!-- Gazebo skid steering pluggins -->
  <!-- xacro:skid_steering broadcastOdomTF="1"/ -->
  <!-- WHEELS -->
  <!-- Wheels -->
  <joint name="left_front_shock" type="prismatic">
    <parent link="base_link"/>
    <child link="left_steering_link"/>
    <origin xyz="0.825                    0.33                    0.0"/>
    <axis xyz="0 0 -1"/>
    <limit effort="100" lower="-0.05" upper="0.05" velocity="1000"/>
  </joint>
  <transmission name="left_front_shock_trans">
    <type>transmission_interface/SimpleTransmission</type>
    <joint name="left_front_shock">
      <hardwareInterface>EffortJointInterface</hardwareInterface>
    </joint>
    <actuator name="left_front_shock_act">
      <!-- This hardwareInterface element exists for compatibility
             with ROS Hydro. -->
      <hardwareInterface>EffortJointInterface</hardwareInterface>
      <mechanicalReduction>1</mechanicalReduction>
    </actuator>
  </transmission>
  <link name="left_steering_link">
    <visual>
      <origin xyz="0 0 0"/>
      <geometry>
        <cylinder length="0.1" radius="0.1"/>
      </geometry>
    </visual>
    <collision>
      <origin xyz="0 0 0"/>
      <geometry>
        <cylinder length="0.1" radius="0.1"/>
      </geometry>
    </collision>
    <xacro:null_inertial/>
  </link>
  <joint name="left_steering_joint" type="revolute">
    <parent link="left_steering_link"/>
    <child link="left_front_axle_carrier"/>
    <axis xyz="0 0 1"/>
    <limit effort="50" lower="-0.785398163" upper="0.785398163" velocity="25"/>
  </joint>
  <transmission name="left_steering_trans">
    <type>transmission_interface/SimpleTransmission</type>
    <joint name="left_steering_joint">
      <hardwareInterface>EffortJointInterface</hardwareInterface>
    </joint>
    <actuator name="left_steering_act">
      <!-- This hardwareInterface element exists for compatibility
             with ROS Hydro. -->
      <hardwareInterface>EffortJointInterface</hardwareInterface>
      <mechanicalReduction>1</mechanicalReduction>
    </actuator>
  </transmission>
  <gazebo reference="left_steering_link">
    <material>Gazebo/Black</material>
  </gazebo>
  <link name="left_front_axle_carrier">
    <visual>
      <origin xyz="0 0 0"/>
      <geometry>
        <cylinder length="0.1" radius="0.1"/>
      </geometry>
    </visual>
    <collision>
      <origin xyz="0 0 0"/>
      <geometry>
        <cylinder length="0.1" radius="0.1"/>
      </geometry>
    </collision>
    <xacro:null_inertial/>
  </link>
  <joint name="left_front_axle" type="continuous">
    <parent link="left_front_axle_carrier"/>
    <child link="left_front_wheel"/>
    <origin rpy="1.57079633 0 3.14159265"/>
    <axis xyz="0 0 -1"/>
    <limit effort="102.5" velocity="39.02"/>
  </joint>
  <transmission name="left_front_axle_trans">
    <type>transmission_interface/SimpleTransmission</type>
    <joint name="left_front_axle">
      <hardwareInterface>EffortJointInterface</hardwareInterface>
    </joint>
    <actuator name="left_front_axle_act">
      <!-- This hardwareInterface element exists for compatibility
             with ROS Hydro. -->
      <hardwareInterface>EffortJointInterface</hardwareInterface>
      <mechanicalReduction>1</mechanicalReduction>
    </actuator>
  </transmission>
  <gazebo reference="left_front_axle_carrier">
    <material>Gazebo/Black</material>
  </gazebo>
  <link name="left_front_wheel">
    <visual>
      <origin xyz="0                      0                      0.14"/>
      <geometry>
        <cylinder length="0.2" radius="0.235"/>
      </geometry>
      <material name="tire_mat"/>
    </visual>
    <collision>
      <origin xyz="0                                           0                      0.14"/>
      <geometry>
        <cylinder length="0.2" radius="0.235"/>
      </geometry>
    </collision>
    <inertial>
      <mass value="8.0"/>
      <inertia ixx="0.164729166667" ixy="0" ixz="0" iyy="0.164729166667" iyz="0" izz="0.276125"/>
    </inertial>
  </link>
  <gazebo reference="left_front_wheel">
    <material>Gazebo/Black</material>
  </gazebo>
  <joint name="right_front_shock" type="prismatic">
    <parent link="base_link"/>
    <child link="right_steering_link"/>
    <origin xyz="0.825                    -0.33                    0.0"/>
    <axis xyz="0 0 -1"/>
    <limit effort="100" lower="-0.05" upper="0.05" velocity="1000"/>
  </joint>
  <transmission name="right_front_shock_trans">
    <type>transmission_interface/SimpleTransmission</type>
    <joint name="right_front_shock">
      <hardwareInterface>EffortJointInterface</hardwareInterface>
    </joint>
    <actuator name="right_front_shock_act">
      <!-- This hardwareInterface element exists for compatibility
             with ROS Hydro. -->
      <hardwareInterface>EffortJointInterface</hardwareInterface>
      <mechanicalReduction>1</mechanicalReduction>
    </actuator>
  </transmission>
  <link name="right_steering_link">
    <visual>
      <origin xyz="0 0 0"/>
      <geometry>
        <cylinder length="0.1" radius="0.1"/>
      </geometry>
    </visual>
    <collision>
      <origin xyz="0 0 0"/>
      <geometry>
        <cylinder length="0.1" radius="0.1"/>
      </geometry>
    </collision>
    <xacro:null_inertial/>
  </link>
  <joint name="right_steering_joint" type="revolute">
    <parent link="right_steering_link"/>
    <child link="right_front_axle_carrier"/>
    <axis xyz="0 0 1"/>
    <limit effort="50" lower="-0.785398163" upper="0.785398163" velocity="25"/>
  </joint>
  <transmission name="right_steering_trans">
    <type>transmission_interface/SimpleTransmission</type>
    <joint name="right_steering_joint">
      <hardwareInterface>EffortJointInterface</hardwareInterface>
    </joint>
    <actuator name="right_steering_act">
      <!-- This hardwareInterface element exists for compatibility
             with ROS Hydro. -->
      <hardwareInterface>EffortJointInterface</hardwareInterface>
      <mechanicalReduction>1</mechanicalReduction>
    </actuator>
  </transmission>
  <gazebo reference="right_steering_link">
    <material>Gazebo/Black</material>
  </gazebo>
  <link name="right_front_axle_carrier">
    <visual>
      <origin xyz="0 0 0"/>
      <geometry>
        <cylinder length="0.1" radius="0.1"/>
      </geometry>
    </visual>
    <collision>
      <origin xyz="0 0 0"/>
      <geometry>
        <cylinder length="0.1" radius="0.1"/>
      </geometry>
    </collision>
    <xacro:null_inertial/>
  </link>
  <joint name="right_front_axle" type="continuous">
    <parent link="right_front_axle_carrier"/>
    <child link="right_front_wheel"/>
    <origin rpy="1.57079633 0 3.14159265"/>
    <axis xyz="0 0 -1"/>
    <limit effort="102.5" velocity="39.02"/>
  </joint>
  <transmission name="right_front_axle_trans">
    <type>transmission_interface/SimpleTransmission</type>
    <joint name="right_front_axle">
      <hardwareInterface>EffortJointInterface</hardwareInterface>
    </joint>
    <actuator name="right_front_axle_act">
      <!-- This hardwareInterface element exists for compatibility
             with ROS Hydro. -->
      <hardwareInterface>EffortJointInterface</hardwareInterface>
      <mechanicalReduction>1</mechanicalReduction>
    </actuator>
  </transmission>
  <gazebo reference="right_front_axle_carrier">
    <material>Gazebo/Black</material>
  </gazebo>
  <link name="right_front_wheel">
    <visual>
      <origin xyz="0                      0                      -0.14"/>
      <geometry>
        <cylinder length="0.2" radius="0.235"/>
      </geometry>
      <material name="tire_mat"/>
    </visual>
    <collision>
      <origin xyz="0                                           0                      -0.14"/>
      <geometry>
        <cylinder length="0.2" radius="0.235"/>
      </geometry>
    </collision>
    <inertial>
      <mass value="8.0"/>
      <inertia ixx="0.164729166667" ixy="0" ixz="0" iyy="0.164729166667" iyz="0" izz="0.276125"/>
    </inertial>
  </link>
  <gazebo reference="right_front_wheel">
    <material>Gazebo/Black</material>
  </gazebo>
  <joint name="left_rear_shock" type="prismatic">
    <parent link="base_link"/>
    <child link="left_rear_axle_carrier"/>
    <origin xyz="-0.825                    0.33                    0.0"/>
    <axis xyz="0 0 -1"/>
    <limit effort="100" lower="-0.05" upper="0.05" velocity="1000"/>
  </joint>
  <transmission name="left_rear_shock_trans">
    <type>transmission_interface/SimpleTransmission</type>
    <joint name="left_rear_shock">
      <hardwareInterface>EffortJointInterface</hardwareInterface>
    </joint>
    <actuator name="left_rear_shock_act">
      <!-- This hardwareInterface element exists for compatibility
             with ROS Hydro. -->
      <hardwareInterface>EffortJointInterface</hardwareInterface>
      <mechanicalReduction>1</mechanicalReduction>
    </actuator>
  </transmission>
  <link name="left_rear_axle_carrier">
    <visual>
      <origin xyz="0 0 0"/>
      <geometry>
        <cylinder length="0.1" radius="0.1"/>
      </geometry>
    </visual>
    <collision>
      <origin xyz="0 0 0"/>
      <geometry>
        <cylinder length="0.1" radius="0.1"/>
      </geometry>
    </collision>
    <xacro:null_inertial/>
  </link>
  <joint name="left_rear_axle" type="continuous">
    <parent link="left_rear_axle_carrier"/>
    <child link="left_rear_wheel"/>
    <origin rpy="1.57079633 0 3.14159265"/>
    <axis xyz="0 0 -1"/>
    <limit effort="102.5" velocity="39.02"/>
  </joint>
  <transmission name="left_rear_axle_trans">
    <type>transmission_interface/SimpleTransmission</type>
    <joint name="left_rear_axle">
      <hardwareInterface>EffortJointInterface</hardwareInterface>
    </joint>
    <actuator name="left_rear_axle_act">
      <!-- This hardwareInterface element exists for compatibility
             with ROS Hydro. -->
      <hardwareInterface>EffortJointInterface</hardwareInterface>
      <mechanicalReduction>1</mechanicalReduction>
    </actuator>
  </transmission>
  <gazebo reference="left_rear_axle_carrier">
    <material>Gazebo/Black</material>
  </gazebo>
  <link name="left_rear_wheel">
    <visual>
      <origin xyz="0                      0                      0.14"/>
      <geometry>
        <cylinder length="0.2" radius="0.235"/>
      </geometry>
      <material name="tire_mat"/>
    </visual>
    <collision>
      <origin xyz="0                                           0                      0.14"/>
      <geometry>
        <cylinder length="0.2" radius="0.235"/>
      </geometry>
    </collision>
    <inertial>
      <mass value="8.0"/>
      <inertia ixx="0.164729166667" ixy="0" ixz="0" iyy="0.164729166667" iyz="0" izz="0.276125"/>
    </inertial>
  </link>
  <gazebo reference="left_rear_wheel">
    <material>Gazebo/Black</material>
  </gazebo>
  <joint name="right_rear_shock" type="prismatic">
    <parent link="base_link"/>
    <child link="right_rear_axle_carrier"/>
    <origin xyz="-0.825                    -0.33                    0.0"/>
    <axis xyz="0 0 -1"/>
    <limit effort="100" lower="-0.05" upper="0.05" velocity="1000"/>
  </joint>
  <transmission name="right_rear_shock_trans">
    <type>transmission_interface/SimpleTransmission</type>
    <joint name="right_rear_shock">
      <hardwareInterface>EffortJointInterface</hardwareInterface>
    </joint>
    <actuator name="right_rear_shock_act">
      <!-- This hardwareInterface element exists for compatibility
             with ROS Hydro. -->
      <hardwareInterface>EffortJointInterface</hardwareInterface>
      <mechanicalReduction>1</mechanicalReduction>
    </actuator>
  </transmission>
  <link name="right_rear_axle_carrier">
    <visual>
      <origin xyz="0 0 0"/>
      <geometry>
        <cylinder length="0.1" radius="0.1"/>
      </geometry>
    </visual>
    <collision>
      <origin xyz="0 0 0"/>
      <geometry>
        <cylinder length="0.1" radius="0.1"/>
      </geometry>
    </collision>
    <xacro:null_inertial/>
  </link>
  <joint name="right_rear_axle" type="continuous">
    <parent link="right_rear_axle_carrier"/>
    <child link="right_rear_wheel"/>
    <origin rpy="1.57079633 0 3.14159265"/>
    <axis xyz="0 0 -1"/>
    <limit effort="102.5" velocity="39.02"/>
  </joint>
  <transmission name="right_rear_axle_trans">
    <type>transmission_interface/SimpleTransmission</type>
    <joint name="right_rear_axle">
      <hardwareInterface>EffortJointInterface</hardwareInterface>
    </joint>
    <actuator name="right_rear_axle_act">
      <!-- This hardwareInterface element exists for compatibility
             with ROS Hydro. -->
      <hardwareInterface>EffortJointInterface</hardwareInterface>
      <mechanicalReduction>1</mechanicalReduction>
    </actuator>
  </transmission>
  <gazebo reference="right_rear_axle_carrier">
    <material>Gazebo/Black</material>
  </gazebo>
  <link name="right_rear_wheel">
    <visual>
      <origin xyz="0                      0                      -0.14"/>
      <geometry>
        <cylinder length="0.2" radius="0.235"/>
      </geometry>
      <material name="tire_mat"/>
    </visual>
    <collision>
      <origin xyz="0                                           0                      -0.14"/>
      <geometry>
        <cylinder length="0.2" radius="0.235"/>
      </geometry>
    </collision>
    <inertial>
      <mass value="8.0"/>
      <inertia ixx="0.164729166667" ixy="0" ixz="0" iyy="0.164729166667" iyz="0" izz="0.276125"/>
    </inertial>
  </link>
  <gazebo reference="right_rear_wheel">
    <material>Gazebo/Black</material>
  </gazebo>
  <!-- SENSORS -->
  <joint name="hokuyo3d_laser_joint" type="fixed">
    <origin rpy="0 0 0" xyz="0.95 0.0 0.1"/>
    <parent link="base_link"/>
    <child link="hokuyo3d_laser_link"/>
  </joint>
  <link name="hokuyo3d_laser_link">
    <collision>
      <origin rpy="0 0 0" xyz="0 0 0"/>
      <geometry>
        <box size="0.1 0.1 0.08"/>
      </geometry>
    </collision>
    <visual>
      <origin rpy="0 0 0" xyz="0 0 0"/>
      <geometry>
        <mesh filename="package://rbcar_description/meshes/sensors/hokuyo3d.dae"/>
      </geometry>
    </visual>
    <inertial>
      <mass value="1e-5"/>
      <origin rpy="0 0 0" xyz="0 0 0"/>
      <inertia ixx="1e-6" ixy="0" ixz="0" iyy="1e-6" iyz="0" izz="1e-6"/>
    </inertial>
  </link>
  <gazebo reference="hokuyo3d_laser_link">
    <sensor name="hokuyo3d_sensor" type="ray">
      <pose>0 0 0 0 0 0</pose>
      <visualize>false</visualize>
      <update_rate>20</update_rate>
      <ray>
        <scan>
          <horizontal>
            <samples>16</samples>
            <resolution>1.0</resolution>
            <min_angle>-1.83591184</min_angle>
            <max_angle>1.83591184</max_angle>
          </horizontal>
          <vertical>
            <samples>162</samples>
            <resolution>1.0</resolution>
            <min_angle>-0.0872664626</min_angle>
            <max_angle>0.610865238</max_angle>
          </vertical>
        </scan>
        <range>
          <min>0.10</min>
          <max>20.0</max>
          <resolution>0.01</resolution>
        </range>
        <noise>
          <type>gaussian</type>
          <mean>0.0</mean>
          <stddev>0.01</stddev>
        </noise>
      </ray>
      <plugin filename="libgazebo_ros_block_laser.so" name="gazebo_ros_head_hokuyo_controller">
        <topicName>hokuyo3d/points2</topicName>
        <frameName>hokuyo3d_laser_link</frameName>
      </plugin>
    </sensor>
  </gazebo>
  <!--xacro:sensor_hokuyo_utm30lx name="hokuyo" parent="base_link">
		<origin xyz="0.0 0.0 0.33" rpy="0 0 0"/>
	</xacro:sensor_hokuyo_utm30lx -->
  <!--
	<xacro:sensor_hokuyo_urg04lx name="hokuyo1" parent="base_link">
		<origin xyz="-0.1 0.0 0.33" rpy="0 0 0"/>
	</xacro:sensor_hokuyo_urg04lx>
-->
  <!-- xacro:sensor_axis name="camera" parent="base_link">
		<origin xyz="0.19 0 0.17" rpy="0 ${15*PI/180} 0"/>
	</xacro:sensor_axis>
  
	<xacro:sensor_imu name="imu" parent="base_link">
		<origin xyz="-0.18 0.0 0.170" rpy="0 0 0"/>
	</xacro:sensor_imu>
  
	<xacro:sensor_gps name="gps" parent="base_link">
		<origin xyz="-0.22 0 0.275" rpy="0 0 0"/>
	</xacro:sensor_gps -->
  <!--
	<xacro:sensor_asus_xtion_pro name="xtion_pro" parent="base_link">
		<origin xyz="0.3 0.0 0.3" rpy="0 0 0"/> 
	</xacro:sensor_asus_xtion_pro>  
-->
  <!--
	<xacro:sensor_kinect name="kinect" parent="base_link">
		<origin xyz="0.3 0.0 0.16" rpy="0 0 0"/> 
	</xacro:sensor_kinect>  
  
-->
  <!--
	<xacro:sensor_fotonic name="fotonic" parent="base_link">
		<origin xyz="0.3 0.0 0.24" rpy="0 0 0"/> 
	</xacro:sensor_fotonic>  
-->
  <gazebo>
    <plugin filename="libgazebo_ros_control.so" name="gazebo_ros_control"/>
  </gazebo>
</robot>

