<?xml version="1.0" ?>
<!-- =================================================================================== -->
<!-- |    This document was autogenerated by xacro from rbcar.urdf.xacro               | -->
<!-- |    EDITING THIS FILE BY HAND IS NOT RECOMMENDED                                 | -->
<!-- =================================================================================== -->
<robot name="rbcar" xmlns:xacro="http://ros.org/wiki/xacro">
  <gazebo reference="base_footprint">
    <material>Gazebo/Green</material>
  </gazebo>
  <xacro:property name="PI" value="3.1415926535897931"/>
  <xacro:property name="wheel_width" value="0.317"/>
  <!-- BASE FOOTPRINT -->
  <link name="base_footprint">
    <visual>
      <origin rpy="0 0 0" xyz="0 0 0"/>
      <geometry>
        <box size="0.001 0.001 0.001"/>
      </geometry>
    </visual>
    <!--
      <collision>
          <origin xyz="0 0 0" rpy="0 0 0" />
          <geometry>
            <box size="0.001 0.001 0.001" />
          </geometry>
      </collision>
-->
  </link>
  <joint name="base_footprint_joint" type="fixed">
    <origin rpy="0 0 0" xyz="0 0 0.150"/>
    <!-- height is the clearance -->
    <parent link="base_footprint"/>
    <child link="base_link"/>
  </joint>
  <!-- BASE_LINK -->
  <link name="base_link">
    <inertial>
      <mass value="125.0"/>
      <origin xyz="0 0 0"/>
      <inertia ixx="1.391" ixy="0.004" ixz="0.0" iyy="6.853" iyz="0.0" izz="6.125"/>
    </inertial>
    <visual>
      <origin rpy="0 0 0" xyz="0 0 0"/>
      <geometry>
        <box size="0.1 0.1 0.1"/>
      </geometry>
      <material name="darkgrey">
        <color rgba="0.1 0.1 0.1 1"/>
      </material>
    </visual>
    <collision>
      <origin rpy="0 0 0 " xyz="0 0 0"/>
      <geometry>
        <box size="0.1 0.1 0.1"/>
      </geometry>
    </collision>
  </link>
  
  <joint name="rear_axle_joint" type="continuous">
    <parent link="base_link"/>
    <child link="rear_axle"/>
    <origin rpy="1.57079633 0 3.14159265"/>
    <axis xyz="0 0 1"/>
    <limit effort="400" velocity="1000"/>
  </joint>
  <transmission name="rear_axle_transmission">
    <type>transmission_interface/SimpleTransmission</type>
    <joint name="rear_axle_joint">
      <hardwareInterface>EffortJointInterface</hardwareInterface>
    </joint>
    <actuator name="rear_axle_actuator">
      <!-- This hardwareInterface element exists for compatibility
             with ROS Hydro. -->
      <hardwareInterface>EffortJointInterface</hardwareInterface>
      <mechanicalReduction>1</mechanicalReduction>
    </actuator>
  </transmission>
  <link name="rear_axle">
    <visual>
      <origin xyz="0                      0                      -0.14"/>
      <geometry>
        <cylinder length="0.2" radius="0.235"/>
      </geometry>
      <material name="tire_mat"/>
    </visual>
    <collision>
      <origin xyz="0                                           0                      -0.14"/>
      <geometry>
        <cylinder length="0.2" radius="0.235"/>
      </geometry>
    </collision>
    <inertial>
      <mass value="8.0"/>
      <inertia ixx="0.164729166667" ixy="0" ixz="0" iyy="0.164729166667" iyz="0" izz="0.276125"/>
    </inertial>
  </link>
</robot>
